import { describe, it, expect, vi, beforeEach } from 'vitest';
import { render, screen } from '@testing-library/react';
import { ErrorBoundary } from '../ErrorBoundary';
import React from 'react';

// Mock logger
vi.mock('@/services/logger', () => ({
  logger: {
    error: vi.fn(),
  },
}));

// Component that throws an error
const ThrowError = ({ shouldThrow }: { shouldThrow: boolean }) => {
  if (shouldThrow) {
    throw new Error('Test error');
  }
  return <div>No error</div>;
};

describe('ErrorBoundary', () => {
  beforeEach(() => {
    vi.clearAllMocks();
    // Suppress console.error for these tests since we're intentionally throwing errors
    vi.spyOn(console, 'error').mockImplementation(() => {});
  });

  afterEach(() => {
    vi.restoreAllMocks();
  });

  it('renders children when there is no error', () => {
    render(
      <ErrorBoundary>
        <ThrowError shouldThrow={false} />
      </ErrorBoundary>
    );

    expect(screen.getByText('No error')).toBeInTheDocument();
  });

  it('renders error UI when there is an error', () => {
    render(
      <ErrorBoundary>
        <ThrowError shouldThrow={true} />
      </ErrorBoundary>
    );

    expect(screen.getByText('Something went wrong')).toBeInTheDocument();
    expect(screen.getByText(/We encountered an unexpected error/)).toBeInTheDocument();
    expect(screen.getByRole('button', { name: /try again/i })).toBeInTheDocument();
    expect(screen.getByRole('button', { name: /go home/i })).toBeInTheDocument();
  });

  it('renders custom fallback when provided', () => {
    const customFallback = <div>Custom error message</div>;

    render(
      <ErrorBoundary fallback={customFallback}>
        <ThrowError shouldThrow={true} />
      </ErrorBoundary>
    );

    expect(screen.getByText('Custom error message')).toBeInTheDocument();
    expect(screen.queryByText('Something went wrong')).not.toBeInTheDocument();
  });

  it('calls onError callback when error occurs', () => {
    const onError = vi.fn();

    render(
      <ErrorBoundary onError={onError}>
        <ThrowError shouldThrow={true} />
      </ErrorBoundary>
    );

    expect(onError).toHaveBeenCalledWith(
      expect.any(Error),
      expect.objectContaining({
        componentStack: expect.any(String),
      })
    );
  });

  it('shows error details in development mode', () => {
    const originalEnv = process.env.NODE_ENV;
    process.env.NODE_ENV = 'development';

    render(
      <ErrorBoundary>
        <ThrowError shouldThrow={true} />
      </ErrorBoundary>
    );

    expect(screen.getByText('Error Details:')).toBeInTheDocument();
    expect(screen.getByText('Test error')).toBeInTheDocument();

    process.env.NODE_ENV = originalEnv;
  });

  it('hides error details in production mode', () => {
    const originalEnv = process.env.NODE_ENV;
    process.env.NODE_ENV = 'production';

    render(
      <ErrorBoundary>
        <ThrowError shouldThrow={true} />
      </ErrorBoundary>
    );

    expect(screen.queryByText('Error Details:')).not.toBeInTheDocument();
    expect(screen.queryByText('Test error')).not.toBeInTheDocument();

    process.env.NODE_ENV = originalEnv;
  });

  it('resets error state when retry button is clicked', () => {
    const { rerender } = render(
      <ErrorBoundary>
        <ThrowError shouldThrow={true} />
      </ErrorBoundary>
    );

    expect(screen.getByText('Something went wrong')).toBeInTheDocument();

    const retryButton = screen.getByRole('button', { name: /try again/i });
    retryButton.click();

    // Re-render with no error
    rerender(
      <ErrorBoundary>
        <ThrowError shouldThrow={false} />
      </ErrorBoundary>
    );

    expect(screen.getByText('No error')).toBeInTheDocument();
  });
});